Traceback (most recent call last):
  File "/usr/local/anaconda3/lib/python3.11/site-packages/jupyter_cache/executors/utils.py", line 58, in single_nb_execution
    executenb(
  File "/usr/local/anaconda3/lib/python3.11/site-packages/nbclient/client.py", line 1204, in execute
    return NotebookClient(nb=nb, resources=resources, km=km, **kwargs).execute()
           ^^^^^^^^^^^^^^^^^^^^^^^^^^^^^^^^^^^^^^^^^^^^^^^^^^^^^^^^^^^^^^^^^^^^^
  File "/usr/local/anaconda3/lib/python3.11/site-packages/nbclient/util.py", line 84, in wrapped
    return just_run(coro(*args, **kwargs))
           ^^^^^^^^^^^^^^^^^^^^^^^^^^^^^^^
  File "/usr/local/anaconda3/lib/python3.11/site-packages/nbclient/util.py", line 62, in just_run
    return loop.run_until_complete(coro)
           ^^^^^^^^^^^^^^^^^^^^^^^^^^^^^
  File "/usr/local/anaconda3/lib/python3.11/asyncio/base_events.py", line 653, in run_until_complete
    return future.result()
           ^^^^^^^^^^^^^^^
  File "/usr/local/anaconda3/lib/python3.11/site-packages/nbclient/client.py", line 663, in async_execute
    await self.async_execute_cell(
  File "/usr/local/anaconda3/lib/python3.11/site-packages/nbclient/client.py", line 965, in async_execute_cell
    await self._check_raise_for_error(cell, cell_index, exec_reply)
  File "/usr/local/anaconda3/lib/python3.11/site-packages/nbclient/client.py", line 862, in _check_raise_for_error
    raise CellExecutionError.from_cell_and_msg(cell, exec_reply_content)
nbclient.exceptions.CellExecutionError: An error occurred while executing the following cell:
------------------
import numpy as np
import matplotlib.pyplot as plt
from scipy import stats
import pandas as pd

# Load data without specifying data types initially
df = pd.read_csv('~/documents/github/csv/donor_live.csv', low_memory=False)

# Print DataFrame info to verify load
print(df.info())

# Clean and convert data types
df['pers_id'] = pd.to_numeric(df['pers_id'], errors='coerce')
df['don_age_in_months'] = pd.to_numeric(df['don_age_in_months'], errors='coerce')
df['don_age'] = pd.to_numeric(df['don_age'], errors='coerce')
df['don_race'] = pd.to_numeric(df['don_race'], errors='coerce')

# Display basic statistics for continuous variables
print(df[['don_age_in_months', 'don_age', 'don_race']].describe())

# Plot histograms for continuous variables
continuous_vars = ['don_age_in_months', 'don_age', 'don_race']

for var in continuous_vars:
    plt.figure()
    df[var].dropna().hist(bins=30)
    plt.title(f'Histogram of {var}')
    plt.xlabel(var)
    plt.ylabel('Frequency')
    plt.show()

# Count and plot binary/categorical variables
binary_vars = ['don_gender', 'don_ethnicity_srtr']
categorical_vars = ['don_ty', 'don_home_state', 'don_race_srtr']

for var in binary_vars + categorical_vars:
    plt.figure()
    df[var].value_counts().plot(kind='bar')
    plt.title(f'Distribution of {var}')
    plt.xlabel(var)
    plt.ylabel('Count')
    plt.show()

------------------

[0;31m---------------------------------------------------------------------------[0m
[0;31mKeyError[0m                                  Traceback (most recent call last)
File [0;32m/usr/local/anaconda3/lib/python3.11/site-packages/pandas/core/indexes/base.py:3802[0m, in [0;36mIndex.get_loc[0;34m(self, key, method, tolerance)[0m
[1;32m   3801[0m [38;5;28;01mtry[39;00m:
[0;32m-> 3802[0m     [38;5;28;01mreturn[39;00m [38;5;28mself[39m[38;5;241m.[39m_engine[38;5;241m.[39mget_loc(casted_key)
[1;32m   3803[0m [38;5;28;01mexcept[39;00m [38;5;167;01mKeyError[39;00m [38;5;28;01mas[39;00m err:

File [0;32m/usr/local/anaconda3/lib/python3.11/site-packages/pandas/_libs/index.pyx:138[0m, in [0;36mpandas._libs.index.IndexEngine.get_loc[0;34m()[0m

File [0;32m/usr/local/anaconda3/lib/python3.11/site-packages/pandas/_libs/index.pyx:165[0m, in [0;36mpandas._libs.index.IndexEngine.get_loc[0;34m()[0m

File [0;32mpandas/_libs/hashtable_class_helper.pxi:5745[0m, in [0;36mpandas._libs.hashtable.PyObjectHashTable.get_item[0;34m()[0m

File [0;32mpandas/_libs/hashtable_class_helper.pxi:5753[0m, in [0;36mpandas._libs.hashtable.PyObjectHashTable.get_item[0;34m()[0m

[0;31mKeyError[0m: 'pers_id'

The above exception was the direct cause of the following exception:

[0;31mKeyError[0m                                  Traceback (most recent call last)
Cell [0;32mIn[3], line 13[0m
[1;32m     10[0m [38;5;28mprint[39m(df[38;5;241m.[39minfo())
[1;32m     12[0m [38;5;66;03m# Clean and convert data types[39;00m
[0;32m---> 13[0m df[[38;5;124m'[39m[38;5;124mpers_id[39m[38;5;124m'[39m] [38;5;241m=[39m pd[38;5;241m.[39mto_numeric(df[[38;5;124m'[39m[38;5;124mpers_id[39m[38;5;124m'[39m], errors[38;5;241m=[39m[38;5;124m'[39m[38;5;124mcoerce[39m[38;5;124m'[39m)
[1;32m     14[0m df[[38;5;124m'[39m[38;5;124mdon_age_in_months[39m[38;5;124m'[39m] [38;5;241m=[39m pd[38;5;241m.[39mto_numeric(df[[38;5;124m'[39m[38;5;124mdon_age_in_months[39m[38;5;124m'[39m], errors[38;5;241m=[39m[38;5;124m'[39m[38;5;124mcoerce[39m[38;5;124m'[39m)
[1;32m     15[0m df[[38;5;124m'[39m[38;5;124mdon_age[39m[38;5;124m'[39m] [38;5;241m=[39m pd[38;5;241m.[39mto_numeric(df[[38;5;124m'[39m[38;5;124mdon_age[39m[38;5;124m'[39m], errors[38;5;241m=[39m[38;5;124m'[39m[38;5;124mcoerce[39m[38;5;124m'[39m)

File [0;32m/usr/local/anaconda3/lib/python3.11/site-packages/pandas/core/frame.py:3807[0m, in [0;36mDataFrame.__getitem__[0;34m(self, key)[0m
[1;32m   3805[0m [38;5;28;01mif[39;00m [38;5;28mself[39m[38;5;241m.[39mcolumns[38;5;241m.[39mnlevels [38;5;241m>[39m [38;5;241m1[39m:
[1;32m   3806[0m     [38;5;28;01mreturn[39;00m [38;5;28mself[39m[38;5;241m.[39m_getitem_multilevel(key)
[0;32m-> 3807[0m indexer [38;5;241m=[39m [38;5;28mself[39m[38;5;241m.[39mcolumns[38;5;241m.[39mget_loc(key)
[1;32m   3808[0m [38;5;28;01mif[39;00m is_integer(indexer):
[1;32m   3809[0m     indexer [38;5;241m=[39m [indexer]

File [0;32m/usr/local/anaconda3/lib/python3.11/site-packages/pandas/core/indexes/base.py:3804[0m, in [0;36mIndex.get_loc[0;34m(self, key, method, tolerance)[0m
[1;32m   3802[0m     [38;5;28;01mreturn[39;00m [38;5;28mself[39m[38;5;241m.[39m_engine[38;5;241m.[39mget_loc(casted_key)
[1;32m   3803[0m [38;5;28;01mexcept[39;00m [38;5;167;01mKeyError[39;00m [38;5;28;01mas[39;00m err:
[0;32m-> 3804[0m     [38;5;28;01mraise[39;00m [38;5;167;01mKeyError[39;00m(key) [38;5;28;01mfrom[39;00m [38;5;21;01merr[39;00m
[1;32m   3805[0m [38;5;28;01mexcept[39;00m [38;5;167;01mTypeError[39;00m:
[1;32m   3806[0m     [38;5;66;03m# If we have a listlike key, _check_indexing_error will raise[39;00m
[1;32m   3807[0m     [38;5;66;03m#  InvalidIndexError. Otherwise we fall through and re-raise[39;00m
[1;32m   3808[0m     [38;5;66;03m#  the TypeError.[39;00m
[1;32m   3809[0m     [38;5;28mself[39m[38;5;241m.[39m_check_indexing_error(key)

[0;31mKeyError[0m: 'pers_id'
KeyError: 'pers_id'

